Workbook

Sheet Dashboard
A1: 26-Week Interview Prep: Progress Dashboard
A3: Overall progress | B3: =COUNTIF(Plan!$A$2:$A$358,"Done") -> 1 | C3: =COUNTA(Plan!$A$2:$A$358) -> 331 | D3: =IF(C3=0,0,B3/C3) -> 0.003021148 | E3: tasks done / total / % | H3: How to use
H4: 1. Go to the Plan tab. Column A has a dropdown: Not started / In progress / Done.
A5: By month | H5: 2. Rows turn green when Done and yellow when In progress.
A6: Month | B6: Done | C6: In progress | D6: Total | E6: % done | H6: 3. Click a "LeetCode" / "GPP" / "Open link" cell to open the resource.
A7: 1 | B7: =COUNTIFS(Plan!$B$2:$B$358,$A7,Plan!$A$2:$A$358,"Done") -> 1 | C7: =COUNTIFS(Plan!$B$2:$B$358,$A7,Plan!$A$2:$A$358,"In progress") -> 0 | D7: =COUNTIF(Plan!$B$2:$B$358,$A7) -> 53 | E7: =IF(D7=0,0,B7/D7) -> 0.018867925 | H7: 4. This dashboard updates automatically. Do not type in the tables here.
A8: 2 | B8: =COUNTIFS(Plan!$B$2:$B$358,$A8,Plan!$A$2:$A$358,"Done") -> 0 | C8: =COUNTIFS(Plan!$B$2:$B$358,$A8,Plan!$A$2:$A$358,"In progress") -> 0 | D8: =COUNTIF(Plan!$B$2:$B$358,$A8) -> 67 | E8: =IF(D8=0,0,B8/D8) -> 0 | H8: 5. Use the filter arrows on the Plan tab to see one week or one category.
A9: 3 | B9: =COUNTIFS(Plan!$B$2:$B$358,$A9,Plan!$A$2:$A$358,"Done") -> 0 | C9: =COUNTIFS(Plan!$B$2:$B$358,$A9,Plan!$A$2:$A$358,"In progress") -> 0 | D9: =COUNTIF(Plan!$B$2:$B$358,$A9) -> 63 | E9: =IF(D9=0,0,B9/D9) -> 0 | H9: 6. Log mistakes in the Mistake Sheet tab and review it every Sunday.
A10: 4 | B10: =COUNTIFS(Plan!$B$2:$B$358,$A10,Plan!$A$2:$A$358,"Done") -> 0 | C10: =COUNTIFS(Plan!$B$2:$B$358,$A10,Plan!$A$2:$A$358,"In progress") -> 0 | D10: =COUNTIF(Plan!$B$2:$B$358,$A10) -> 67 | E10: =IF(D10=0,0,B10/D10) -> 0
A11: 5 | B11: =COUNTIFS(Plan!$B$2:$B$358,$A11,Plan!$A$2:$A$358,"Done") -> 0 | C11: =COUNTIFS(Plan!$B$2:$B$358,$A11,Plan!$A$2:$A$358,"In progress") -> 0 | D11: =COUNTIF(Plan!$B$2:$B$358,$A11) -> 59 | E11: =IF(D11=0,0,B11/D11) -> 0 | H11: Weekly rhythm
A12: 6 | B12: =COUNTIFS(Plan!$B$2:$B$358,$A12,Plan!$A$2:$A$358,"Done") -> 0 | C12: =COUNTIFS(Plan!$B$2:$B$358,$A12,Plan!$A$2:$A$358,"In progress") -> 0 | D12: =COUNTIF(Plan!$B$2:$B$358,$A12) -> 22 | E12: =IF(D12=0,0,B12/D12) -> 0 | H12: Mon-Thu: DSA, 2 hrs/day (4-6 core problems/week; Stretch rows are optional)
H13: Weekdays: 0.5-1 hr reading (C++ Mon/Tue, design Wed/Thu, recall Fri)
A14: By category | H14: Fri: C++ build with tests (2 hrs)
A15: Category | B15: Done | C15: In progress | D15: Total | E15: % done | H15: Sat (5 hrs): system design / LLD practice + 1 hr portfolio (to Week 17)
A16: DSA | B16: =COUNTIFS(Plan!$D$2:$D$358,$A16,Plan!$A$2:$A$358,"Done") -> 1 | C16: =COUNTIFS(Plan!$D$2:$D$358,$A16,Plan!$A$2:$A$358,"In progress") -> 0 | D16: =COUNTIF(Plan!$D$2:$D$358,$A16) -> 140 | E16: =IF(D16=0,0,B16/D16) -> 0.0071428571 | H16: Sun (5 hrs): Mistake Sheet review, timed DSA (from Week 5), mock (every 3rd week from Week 6), career task
A17: C++ build | B17: =COUNTIFS(Plan!$D$2:$D$358,$A17,Plan!$A$2:$A$358,"Done") -> 0 | C17: =COUNTIFS(Plan!$D$2:$D$358,$A17,Plan!$A$2:$A$358,"In progress") -> 0 | D17: =COUNTIF(Plan!$D$2:$D$358,$A17) -> 22 | E17: =IF(D17=0,0,B17/D17) -> 0
A18: Reading: C++ | B18: =COUNTIFS(Plan!$D$2:$D$358,$A18,Plan!$A$2:$A$358,"Done") -> 0 | C18: =COUNTIFS(Plan!$D$2:$D$358,$A18,Plan!$A$2:$A$358,"In progress") -> 0 | D18: =COUNTIF(Plan!$D$2:$D$358,$A18) -> 25 | E18: =IF(D18=0,0,B18/D18) -> 0 | H18: Reading key
A19: Reading: Design | B19: =COUNTIFS(Plan!$D$2:$D$358,$A19,Plan!$A$2:$A$358,"Done") -> 0 | C19: =COUNTIFS(Plan!$D$2:$D$358,$A19,Plan!$A$2:$A$358,"In progress") -> 0 | D19: =COUNTIF(Plan!$D$2:$D$358,$A19) -> 31 | E19: =IF(D19=0,0,B19/D19) -> 0 | H19: EMC++ = Effective Modern C++ (Meyers); CIA = C++ Concurrency in Action
A20: Saturday design | B20: =COUNTIFS(Plan!$D$2:$D$358,$A20,Plan!$A$2:$A$358,"Done") -> 0 | C20: =COUNTIFS(Plan!$D$2:$D$358,$A20,Plan!$A$2:$A$358,"In progress") -> 0 | D20: =COUNTIF(Plan!$D$2:$D$358,$A20) -> 24 | E20: =IF(D20=0,0,B20/D20) -> 0 | H20: GPP = Game Programming Patterns (gameprogrammingpatterns.com)
A21: Sunday career | B21: =COUNTIFS(Plan!$D$2:$D$358,$A21,Plan!$A$2:$A$358,"Done") -> 0 | C21: =COUNTIFS(Plan!$D$2:$D$358,$A21,Plan!$A$2:$A$358,"In progress") -> 0 | D21: =COUNTIF(Plan!$D$2:$D$358,$A21) -> 13 | E21: =IF(D21=0,0,B21/D21) -> 0 | H21: Xu1/Xu2 = System Design Interview Vol 1/2; DDIA = Designing Data-Intensive Applications
A22: Checkpoint | B22: =COUNTIFS(Plan!$D$2:$D$358,$A22,Plan!$A$2:$A$358,"Done") -> 0 | C22: =COUNTIFS(Plan!$D$2:$D$358,$A22,Plan!$A$2:$A$358,"In progress") -> 0 | D22: =COUNTIF(Plan!$D$2:$D$358,$A22) -> 1 | E22: =IF(D22=0,0,B22/D22) -> 0 | H22: Stretch/Extra practice rows are optional.
A23: Interview prep | B23: =COUNTIFS(Plan!$D$2:$D$358,$A23,Plan!$A$2:$A$358,"Done") -> 0 | C23: =COUNTIFS(Plan!$D$2:$D$358,$A23,Plan!$A$2:$A$358,"In progress") -> 0 | D23: =COUNTIF(Plan!$D$2:$D$358,$A23) -> 9 | E23: =IF(D23=0,0,B23/D23) -> 0
A24: Mock interview | B24: =COUNTIFS(Plan!$D$2:$D$358,$A24,Plan!$A$2:$A$358,"Done") -> 0 | C24: =COUNTIFS(Plan!$D$2:$D$358,$A24,Plan!$A$2:$A$358,"In progress") -> 0 | D24: =COUNTIF(Plan!$D$2:$D$358,$A24) -> 13 | E24: =IF(D24=0,0,B24/D24) -> 0
A25: Portfolio | B25: =COUNTIFS(Plan!$D$2:$D$358,$A25,Plan!$A$2:$A$358,"Done") -> 0 | C25: =COUNTIFS(Plan!$D$2:$D$358,$A25,Plan!$A$2:$A$358,"In progress") -> 0 | D25: =COUNTIF(Plan!$D$2:$D$358,$A25) -> 17 | E25: =IF(D25=0,0,B25/D25) -> 0
A26: Revision | B26: =COUNTIFS(Plan!$D$2:$D$358,$A26,Plan!$A$2:$A$358,"Done") -> 0 | C26: =COUNTIFS(Plan!$D$2:$D$358,$A26,Plan!$A$2:$A$358,"In progress") -> 0 | D26: =COUNTIF(Plan!$D$2:$D$358,$A26) -> 36 | E26: =IF(D26=0,0,B26/D26) -> 0
A28: By week
A29: Week | B29: Done | C29: In progress | D29: Total | E29: % done
A30: 1 | B30: =COUNTIFS(Plan!$C$2:$C$358,$A30,Plan!$A$2:$A$358,"Done") -> 1 | C30: =COUNTIFS(Plan!$C$2:$C$358,$A30,Plan!$A$2:$A$358,"In progress") -> 0 | D30: =COUNTIF(Plan!$C$2:$C$358,$A30) -> 15 | E30: =IF(D30=0,0,B30/D30) -> 0.066666667
A31: 2 | B31: =COUNTIFS(Plan!$C$2:$C$358,$A31,Plan!$A$2:$A$358,"Done") -> 0 | C31: =COUNTIFS(Plan!$C$2:$C$358,$A31,Plan!$A$2:$A$358,"In progress") -> 0 | D31: =COUNTIF(Plan!$C$2:$C$358,$A31) -> 12 | E31: =IF(D31=0,0,B31/D31) -> 0
A32: 3 | B32: =COUNTIFS(Plan!$C$2:$C$358,$A32,Plan!$A$2:$A$358,"Done") -> 0 | C32: =COUNTIFS(Plan!$C$2:$C$358,$A32,Plan!$A$2:$A$358,"In progress") -> 0 | D32: =COUNTIF(Plan!$C$2:$C$358,$A32) -> 12 | E32: =IF(D32=0,0,B32/D32) -> 0
A33: 4 | B33: =COUNTIFS(Plan!$C$2:$C$358,$A33,Plan!$A$2:$A$358,"Done") -> 0 | C33: =COUNTIFS(Plan!$C$2:$C$358,$A33,Plan!$A$2:$A$358,"In progress") -> 0 | D33: =COUNTIF(Plan!$C$2:$C$358,$A33) -> 14 | E33: =IF(D33=0,0,B33/D33) -> 0
A34: 5 | B34: =COUNTIFS(Plan!$C$2:$C$358,$A34,Plan!$A$2:$A$358,"Done") -> 0 | C34: =COUNTIFS(Plan!$C$2:$C$358,$A34,Plan!$A$2:$A$358,"In progress") -> 0 | D34: =COUNTIF(Plan!$C$2:$C$358,$A34) -> 19 | E34: =IF(D34=0,0,B34/D34) -> 0
A35: 6 | B35: =COUNTIFS(Plan!$C$2:$C$358,$A35,Plan!$A$2:$A$358,"Done") -> 0 | C35: =COUNTIFS(Plan!$C$2:$C$358,$A35,Plan!$A$2:$A$358,"In progress") -> 0 | D35: =COUNTIF(Plan!$C$2:$C$358,$A35) -> 15 | E35: =IF(D35=0,0,B35/D35) -> 0
A36: 7 | B36: =COUNTIFS(Plan!$C$2:$C$358,$A36,Plan!$A$2:$A$358,"Done") -> 0 | C36: =COUNTIFS(Plan!$C$2:$C$358,$A36,Plan!$A$2:$A$358,"In progress") -> 0 | D36: =COUNTIF(Plan!$C$2:$C$358,$A36) -> 15 | E36: =IF(D36=0,0,B36/D36) -> 0
A37: 8 | B37: =COUNTIFS(Plan!$C$2:$C$358,$A37,Plan!$A$2:$A$358,"Done") -> 0 | C37: =COUNTIFS(Plan!$C$2:$C$358,$A37,Plan!$A$2:$A$358,"In progress") -> 0 | D37: =COUNTIF(Plan!$C$2:$C$358,$A37) -> 18 | E37: =IF(D37=0,0,B37/D37) -> 0
A38: 9 | B38: =COUNTIFS(Plan!$C$2:$C$358,$A38,Plan!$A$2:$A$358,"Done") -> 0 | C38: =COUNTIFS(Plan!$C$2:$C$358,$A38,Plan!$A$2:$A$358,"In progress") -> 0 | D38: =COUNTIF(Plan!$C$2:$C$358,$A38) -> 15 | E38: =IF(D38=0,0,B38/D38) -> 0
A39: 10 | B39: =COUNTIFS(Plan!$C$2:$C$358,$A39,Plan!$A$2:$A$358,"Done") -> 0 | C39: =COUNTIFS(Plan!$C$2:$C$358,$A39,Plan!$A$2:$A$358,"In progress") -> 0 | D39: =COUNTIF(Plan!$C$2:$C$358,$A39) -> 18 | E39: =IF(D39=0,0,B39/D39) -> 0
A40: 11 | B40: =COUNTIFS(Plan!$C$2:$C$358,$A40,Plan!$A$2:$A$358,"Done") -> 0 | C40: =COUNTIFS(Plan!$C$2:$C$358,$A40,Plan!$A$2:$A$358,"In progress") -> 0 | D40: =COUNTIF(Plan!$C$2:$C$358,$A40) -> 15 | E40: =IF(D40=0,0,B40/D40) -> 0
A41: 12 | B41: =COUNTIFS(Plan!$C$2:$C$358,$A41,Plan!$A$2:$A$358,"Done") -> 0 | C41: =COUNTIFS(Plan!$C$2:$C$358,$A41,Plan!$A$2:$A$358,"In progress") -> 0 | D41: =COUNTIF(Plan!$C$2:$C$358,$A41) -> 15 | E41: =IF(D41=0,0,B41/D41) -> 0
... A55: 26 | B55: =COUNTIFS(Plan!$C$2:$C$358,$A55,Plan!$A$2:$A$358,"Done") -> 0 | C55: =COUNTIFS(Plan!$C$2:$C$358,$A55,Plan!$A$2:$A$358,"In progress") -> 0 | D55: =COUNTIF(Plan!$C$2:$C$358,$A55) -> 2 | E55: =IF(D55=0,0,B55/D55) -> 0

Sheet Plan
A1: Status | B1: Month | C1: Week | D1: Category | E1: Task | F1: Link | G1: More links
D2: Week 1 plan | E2: DSA: Arrays & hashing: duplicates, anagrams, two sum, top-K C++: Dynamic array (vector); type deduction and `auto` (EMC++ 1-6) System design: Singleton and dependency injection (GPP)
A3: Done | B3: 1 | C3: 1 | D3: DSA | E3: Contains Duplicate | F3: LeetCode
A4: Not started | B4: 1 | C4: 1 | D4: DSA | E4: Valid Anagram | F4: LeetCode
A5: Not started | B5: 1 | C5: 1 | D5: DSA | E5: Two Sum | F5: LeetCode
A6: Not started | B6: 1 | C6: 1 | D6: DSA | E6: Group Anagrams | F6: LeetCode
A7: Not started | B7: 1 | C7: 1 | D7: DSA | E7: Top K Frequent Elements | F7: LeetCode
A8: Not started | B8: 1 | C8: 1 | D8: DSA | E8: (Stretch) Product of Array Except Self | F8: LeetCode
A9: Not started | B9: 1 | C9: 1 | D9: DSA | E9: (Stretch) Valid Sudoku | F9: LeetCode
A10: Not started | B10: 1 | C10: 1 | D10: DSA | E10: (Stretch) Encode and Decode Strings (premium on LeetCode; use the free LintCode or NeetCode version)
A11: Not started | B11: 1 | C11: 1 | D11: C++ build | E11: dynamic array (vector)
A12: Not started | B12: 1 | C12: 1 | D12: Reading: C++ | E12: EMC++ Items 1-6 (type deduction, `auto`)
A13: Not started | B13: 1 | C13: 1 | D13: Reading: Design | E13: GPP Singleton | F13: GPP
A14: Not started | B14: 1 | C14: 1 | D14: Saturday design | E14: redesign a singleton-based module (logger or config manager) with dependency injection, on paper
A15: Not started | B15: 1 | C15: 1 | D15: Portfolio | E15: Create the GitHub repo `cpp-toolkit`: CMake, GoogleTest or Catch2, README skeleton; add your vector
A16: Not started | B16: 1 | C16: 1 | D16: Revision | E16: Review the Mistake Sheet; re-solve 2 problems you missed
A17: Not started | B17: 1 | C17: 1 | D17: Sunday career | E17: rewrite resume bullets with metrics
D18: Week 2 plan | E18: DSA: Two pointers: palindrome, 3Sum, container with most water, trapping rain water C++: `unique_ptr`; special member functions and smart pointers (EMC++ 17-22) System design: State pattern, pimpl; vending-machine state machine
A19: Not started | B19: 1 | C19: 2 | D19: DSA | E19: Valid Palindrome | F19: LeetCode
A20: Not started | B20: 1 | C20: 2 | D20: DSA | E20: Two Sum II | F20: LeetCode
A21: Not started | B21: 1 | C21: 2 | D21: DSA | E21: 3Sum | F21: LeetCode
A22: Not started | B22: 1 | C22: 2 | D22: DSA | E22: Container With Most Water | F22: LeetCode
A23: Not started | B23: 1 | C23: 2 | D23: DSA | E23: Trapping Rain Water | F23: LeetCode
A24: Not started | B24: 1 | C24: 2 | D24: C++ build | E24: `unique_ptr`
A25: Not started | B25: 1 | C25: 2 | D25: Reading: C++ | E25: EMC++ Items 17-22 (special member functions, smart pointers)
A26: Not started | B26: 1 | C26: 2 | D26: Reading: Design | E26: GPP State; pimpl idiom on cppreference | F26: GPP | G26: https://en.cppreference.com/w/cpp/language/pimpl
A27: Not started | B27: 1 | C27: 2 | D27: Saturday design | E27: model a vending-machine or traffic-light flow (idle, selecting, paying, dispensing) as a C++ state machine
A28: Not started | B28: 1 | C28: 2 | D28: Portfolio | E28: Add your `unique_ptr` with tests; set up GitHub Actions CI (build + test)
A29: Not started | B29: 1 | C29: 2 | D29: Revision | E29: Review the Mistake Sheet; re-solve 2 problems you missed
A30: Not started | B30: 1 | C30: 2 | D30: Sunday career | E30: finish resume bullets
D31: Week 3 plan | E31: DSA: Sliding window: best time to trade, longest substring, permutation in string C++: `shared_ptr` / `weak_ptr`; move semantics and forwarding references (EMC++ 23-26) System design: Observer and Event Queue; in-process event bus
A32: Not started | B32: 1 | C32: 3 | D32: DSA | E32: Best Time to Buy and Sell Stock | F32: LeetCode
A33: Not started | B33: 1 | C33: 3 | D33: DSA | E33: Longest Substring Without Repeating Characters | F33: LeetCode
A34: Not started | B34: 1 | C34: 3 | D34: DSA | E34: Longest Repeating Character Replacement | F34: LeetCode
A35: Not started | B35: 1 | C35: 3 | D35: DSA | E35: Permutation in String | F35: LeetCode
A36: Not started | B36: 1 | C36: 3 | D36: DSA | E36: (Stretch) Minimum Window Substring | F36: LeetCode
A37: Not started | B37: 1 | C37: 3 | D37: C++ build | E37: `shared_ptr` / `weak_ptr` basics
A38: Not started | B38: 1 | C38: 3 | D38: Reading: C++ | E38: EMC++ Items 23-26 (move semantics, forwarding references)
A39: Not started | B39: 1 | C39: 3 | D39: Reading: Design | E39: GPP Observer, Event Queue | F39: GPP | G39: https://gameprogrammingpatterns.com/event-queue.html
A40: Not started | B40: 1 | C40: 3 | D40: Saturday design | E40: design an in-process event bus / pub-sub: ownership, lifetime and unsubscribe bugs
...

Sheet Mistake Sheet
A1: Date | B1: Problem | C1: Pattern / Topic | D1: What I missed | E1: Re-solved on | F1: Notes
A2: Example: 2026-10-05 | B2: Trapping Rain Water | C2: Two pointers | D2: Forgot to move the pointer with the smaller height | F2: Re-solve next Sunday

Sheet Sheet1
A1: bhvcZ | B1: HOW TO
A2: VS Code snippet | B2: 1. Open the Command Palette
B3: 2. Run: Preferences: Configure User Snippets
B4: 3. Choose C++ or create a global snippet file
